wandb: Currently logged in as: aiotlab (use `wandb login --relogin` to force relogin)
wandb: wandb version 0.12.11 is available!  To upgrade, please run:
wandb:  $ pip install wandb --upgrade
wandb: Tracking run with wandb version 0.12.9
wandb: Syncing run FedAVG-Equal-100-01
wandb:  View project at https://wandb.ai/aiotlab/FL-FedAvg-Rerun
wandb:  View run at https://wandb.ai/aiotlab/FL-FedAvg-Rerun/runs/21lf5fpc
wandb: Run data is saved locally in /local/9511369.1.gpu/9511369/wandb/run-20220310_160049-21lf5fpc
wandb: Run `wandb offline` to turn off syncing.

>>> START RUNNING: FedAVG-Equal-100-01 - Train mode: benchmark - Dataset: cifar100
Traceback (most recent call last):
  File "/apps/centos7/python/3.8.7/lib/python3.8/urllib/request.py", line 1350, in do_open
    h.request(req.get_method(), req.selector, req.data, headers,
  File "/apps/centos7/python/3.8.7/lib/python3.8/http/client.py", line 1255, in request
    self._send_request(method, url, body, headers, encode_chunked)
  File "/apps/centos7/python/3.8.7/lib/python3.8/http/client.py", line 1301, in _send_request
    self.endheaders(body, encode_chunked=encode_chunked)
  File "/apps/centos7/python/3.8.7/lib/python3.8/http/client.py", line 1250, in endheaders
    self._send_output(message_body, encode_chunked=encode_chunked)
  File "/apps/centos7/python/3.8.7/lib/python3.8/http/client.py", line 1010, in _send_output
    self.send(msg)
  File "/apps/centos7/python/3.8.7/lib/python3.8/http/client.py", line 950, in send
    self.connect()
  File "/apps/centos7/python/3.8.7/lib/python3.8/http/client.py", line 1417, in connect
    super().connect()
  File "/apps/centos7/python/3.8.7/lib/python3.8/http/client.py", line 921, in connect
    self.sock = self._create_connection(
  File "/apps/centos7/python/3.8.7/lib/python3.8/socket.py", line 808, in create_connection
    raise err
  File "/apps/centos7/python/3.8.7/lib/python3.8/socket.py", line 796, in create_connection
    sock.connect(sa)
TimeoutError: [Errno 110] Connection timed out

During handling of the above exception, another exception occurred:

Traceback (most recent call last):
  File "train.py", line 345, in <module>
    main(args)
  File "train.py", line 122, in main
    train_dataset, test_dataset, list_idx_sample = load_dataset(
  File "train.py", line 70, in load_dataset
    train_dataset = datasets.CIFAR10(
  File "/home/acc13085dy/federated-learning/FLenv/lib/python3.8/site-packages/torchvision/datasets/cifar.py", line 65, in __init__
    self.download()
  File "/home/acc13085dy/federated-learning/FLenv/lib/python3.8/site-packages/torchvision/datasets/cifar.py", line 143, in download
    download_and_extract_archive(self.url, self.root, filename=self.filename, md5=self.tgz_md5)
  File "/home/acc13085dy/federated-learning/FLenv/lib/python3.8/site-packages/torchvision/datasets/utils.py", line 316, in download_and_extract_archive
    download_url(url, download_root, filename, md5)
  File "/home/acc13085dy/federated-learning/FLenv/lib/python3.8/site-packages/torchvision/datasets/utils.py", line 124, in download_url
    url = _get_redirect_url(url, max_hops=max_redirect_hops)
  File "/home/acc13085dy/federated-learning/FLenv/lib/python3.8/site-packages/torchvision/datasets/utils.py", line 75, in _get_redirect_url
    with urllib.request.urlopen(urllib.request.Request(url, headers=headers)) as response:
  File "/apps/centos7/python/3.8.7/lib/python3.8/urllib/request.py", line 222, in urlopen
    return opener.open(url, data, timeout)
  File "/apps/centos7/python/3.8.7/lib/python3.8/urllib/request.py", line 525, in open
    response = self._open(req, data)
  File "/apps/centos7/python/3.8.7/lib/python3.8/urllib/request.py", line 542, in _open
    result = self._call_chain(self.handle_open, protocol, protocol +
  File "/apps/centos7/python/3.8.7/lib/python3.8/urllib/request.py", line 502, in _call_chain
    result = func(*args)
  File "/apps/centos7/python/3.8.7/lib/python3.8/urllib/request.py", line 1393, in https_open
    return self.do_open(http.client.HTTPSConnection, req,
  File "/apps/centos7/python/3.8.7/lib/python3.8/urllib/request.py", line 1353, in do_open
    raise URLError(err)
urllib.error.URLError: <urlopen error [Errno 110] Connection timed out>

wandb: Waiting for W&B process to finish, PID 186496... (failed 1). Press ctrl-c to abort syncing.
wandb: - 0.00MB of 0.00MB uploaded (0.00MB deduped)wandb: \ 0.00MB of 0.00MB uploaded (0.00MB deduped)wandb: | 0.00MB of 0.00MB uploaded (0.00MB deduped)wandb: / 0.00MB of 0.01MB uploaded (0.00MB deduped)wandb: - 0.00MB of 0.01MB uploaded (0.00MB deduped)wandb: \ 0.00MB of 0.01MB uploaded (0.00MB deduped)wandb: | 0.01MB of 0.01MB uploaded (0.00MB deduped)wandb: / 0.01MB of 0.01MB uploaded (0.00MB deduped)wandb: - 0.01MB of 0.01MB uploaded (0.00MB deduped)wandb: \ 0.01MB of 0.01MB uploaded (0.00MB deduped)wandb: | 0.01MB of 0.01MB uploaded (0.00MB deduped)wandb: / 0.01MB of 0.01MB uploaded (0.00MB deduped)wandb:                                                                                
wandb: Synced 5 W&B file(s), 0 media file(s), 0 artifact file(s) and 0 other file(s)
wandb: Synced FedAVG-Equal-100-01: https://wandb.ai/aiotlab/FL-FedAvg-Rerun/runs/21lf5fpc
wandb: Find logs at: ./wandb/run-20220310_160049-21lf5fpc/logs/debug.log
wandb: 
