wandb: Currently logged in as: aiotlab (use `wandb login --relogin` to force relogin)
wandb: Tracking run with wandb version 0.12.9
wandb: Syncing run FedRL-Fixed-Equal-Non-IID-02
wandb:  View project at https://wandb.ai/aiotlab/federated-learning-dqn
wandb:  View run at https://wandb.ai/aiotlab/federated-learning-dqn/runs/3r1ped8k
wandb: Run data is saved locally in /local/9046937.1.gpu/9046937/wandb/run-20220125_205901-3r1ped8k
wandb: Run `wandb offline` to turn off syncing.

>>> START RUNNING: FedRL-Fixed-Equal-Non-IID-02 - Train mode: RL-Fixed - Dataset: cifar100
Traceback (most recent call last):
  File "/apps/centos7/python/3.8.7/lib/python3.8/urllib/request.py", line 1350, in do_open
    h.request(req.get_method(), req.selector, req.data, headers,
  File "/apps/centos7/python/3.8.7/lib/python3.8/http/client.py", line 1255, in request
    self._send_request(method, url, body, headers, encode_chunked)
  File "/apps/centos7/python/3.8.7/lib/python3.8/http/client.py", line 1301, in _send_request
    self.endheaders(body, encode_chunked=encode_chunked)
  File "/apps/centos7/python/3.8.7/lib/python3.8/http/client.py", line 1250, in endheaders
    self._send_output(message_body, encode_chunked=encode_chunked)
  File "/apps/centos7/python/3.8.7/lib/python3.8/http/client.py", line 1010, in _send_output
    self.send(msg)
  File "/apps/centos7/python/3.8.7/lib/python3.8/http/client.py", line 950, in send
    self.connect()
  File "/apps/centos7/python/3.8.7/lib/python3.8/http/client.py", line 1424, in connect
    self.sock = self._context.wrap_socket(self.sock,
  File "/apps/centos7/python/3.8.7/lib/python3.8/ssl.py", line 500, in wrap_socket
    return self.sslsocket_class._create(
  File "/apps/centos7/python/3.8.7/lib/python3.8/ssl.py", line 1040, in _create
    self.do_handshake()
  File "/apps/centos7/python/3.8.7/lib/python3.8/ssl.py", line 1309, in do_handshake
    self._sslobj.do_handshake()
TimeoutError: [Errno 110] Connection timed out

During handling of the above exception, another exception occurred:

Traceback (most recent call last):
  File "train.py", line 340, in <module>
    main(args)
  File "train.py", line 119, in main
    train_dataset, test_dataset, list_idx_sample = load_dataset(
  File "train.py", line 67, in load_dataset
    train_dataset = datasets.CIFAR10(
  File "/home/acc13085dy/federated-learning/FLenv/lib/python3.8/site-packages/torchvision/datasets/cifar.py", line 65, in __init__
    self.download()
  File "/home/acc13085dy/federated-learning/FLenv/lib/python3.8/site-packages/torchvision/datasets/cifar.py", line 143, in download
    download_and_extract_archive(self.url, self.root, filename=self.filename, md5=self.tgz_md5)
  File "/home/acc13085dy/federated-learning/FLenv/lib/python3.8/site-packages/torchvision/datasets/utils.py", line 316, in download_and_extract_archive
    download_url(url, download_root, filename, md5)
  File "/home/acc13085dy/federated-learning/FLenv/lib/python3.8/site-packages/torchvision/datasets/utils.py", line 124, in download_url
    url = _get_redirect_url(url, max_hops=max_redirect_hops)
  File "/home/acc13085dy/federated-learning/FLenv/lib/python3.8/site-packages/torchvision/datasets/utils.py", line 75, in _get_redirect_url
    with urllib.request.urlopen(urllib.request.Request(url, headers=headers)) as response:
  File "/apps/centos7/python/3.8.7/lib/python3.8/urllib/request.py", line 222, in urlopen
    return opener.open(url, data, timeout)
  File "/apps/centos7/python/3.8.7/lib/python3.8/urllib/request.py", line 525, in open
    response = self._open(req, data)
  File "/apps/centos7/python/3.8.7/lib/python3.8/urllib/request.py", line 542, in _open
    result = self._call_chain(self.handle_open, protocol, protocol +
  File "/apps/centos7/python/3.8.7/lib/python3.8/urllib/request.py", line 502, in _call_chain
    result = func(*args)
  File "/apps/centos7/python/3.8.7/lib/python3.8/urllib/request.py", line 1393, in https_open
    return self.do_open(http.client.HTTPSConnection, req,
  File "/apps/centos7/python/3.8.7/lib/python3.8/urllib/request.py", line 1353, in do_open
    raise URLError(err)
urllib.error.URLError: <urlopen error [Errno 110] Connection timed out>

wandb: Waiting for W&B process to finish, PID 230335... (failed 1). Press ctrl-c to abort syncing.
wandb: - 0.00MB of 0.00MB uploaded (0.00MB deduped)wandb: \ 0.00MB of 0.00MB uploaded (0.00MB deduped)wandb: | 0.00MB of 0.00MB uploaded (0.00MB deduped)wandb: / 0.00MB of 0.01MB uploaded (0.00MB deduped)wandb: - 0.00MB of 0.01MB uploaded (0.00MB deduped)wandb: \ 0.01MB of 0.01MB uploaded (0.00MB deduped)wandb: | 0.01MB of 0.01MB uploaded (0.00MB deduped)wandb: / 0.01MB of 0.01MB uploaded (0.00MB deduped)wandb: - 0.01MB of 0.01MB uploaded (0.00MB deduped)wandb: \ 0.01MB of 0.01MB uploaded (0.00MB deduped)wandb: | 0.01MB of 0.01MB uploaded (0.00MB deduped)wandb: / 0.01MB of 0.01MB uploaded (0.00MB deduped)wandb:                                                                                
wandb: Synced 5 W&B file(s), 0 media file(s), 0 artifact file(s) and 0 other file(s)
wandb: Synced FedRL-Fixed-Equal-Non-IID-02: https://wandb.ai/aiotlab/federated-learning-dqn/runs/3r1ped8k
wandb: Find logs at: ./wandb/run-20220125_205901-3r1ped8k/logs/debug.log
wandb: 
